<?xml version="1.0" encoding="utf-8"?>
<!-- This URDF was automatically created by SolidWorks to URDF Exporter! Originally created by Stephen Brawner (brawner@gmail.com) 
     Commit Version: 1.5.1-0-g916b5db  Build Version: 1.5.7152.31018
     For more information, please see http://wiki.ros.org/sw_urdf_exporter -->
<robot
  name="RescueBot_Baugruppe.SLDASM">
  <link
    name="base_link">
    <inertial>
      <origin
        xyz="-2.6138E-05 0.53594 0.80009"
        rpy="0 0 0" />
      <mass
        value="8.2963" />
      <inertia
        ixx="0.033177"
        ixy="2.1543E-05"
        ixz="-0.00017853"
        iyy="0.022608"
        iyz="-7.7278E-05"
        izz="0.033768" />
    </inertial>
    <visual>
      <origin
        xyz="0 0 0"
        rpy="0 0 0" />
      <geometry>
        <mesh
          filename="package://RescueBot_Baugruppe.SLDASM/meshes/base_link.STL" />
      </geometry>
      <material
        name="">
        <color
          rgba="0.89804 0.91765 0.92941 1" />
      </material>
    </visual>
    <collision>
      <origin
        xyz="0 0 0"
        rpy="0 0 0" />
      <geometry>
        <mesh
          filename="package://RescueBot_Baugruppe.SLDASM/meshes/base_link.STL" />
      </geometry>
    </collision>
  </link>
  <link
    name="schulterGelenk">
    <inertial>
      <origin
        xyz="2.2676E-08 0.087777 -9.73E-05"
        rpy="0 0 0" />
      <mass
        value="8.2963" />
      <inertia
        ixx="0.033127"
        ixy="-1.022E-08"
        ixz="-4.1606E-08"
        iyy="0.022608"
        iyz="8.0225E-05"
        izz="0.033818" />
    </inertial>
    <visual>
      <origin
        xyz="0 0 0"
        rpy="0 0 0" />
      <geometry>
        <mesh
          filename="package://RescueBot_Baugruppe.SLDASM/meshes/schulterGelenk.STL" />
      </geometry>
      <material
        name="">
        <color
          rgba="0.89804 0.91765 0.92941 1" />
      </material>
    </visual>
    <collision>
      <origin
        xyz="0 0 0"
        rpy="0 0 0" />
      <geometry>
        <mesh
          filename="package://RescueBot_Baugruppe.SLDASM/meshes/schulterGelenk.STL" />
      </geometry>
    </collision>
  </link>
  <joint
    name="schulter"
    type="fixed">
    <origin
      xyz="0 -0.799999999999999 0.448167457544184"
      rpy="1.5707963267949 0 2.86985130632957" />
    <parent
      link="base_link" />
    <child
      link="schulterGelenk" />
    <axis
      xyz="0 0 0" />
  </joint>
  <link
    name="ellenbogen">
    <inertial>
      <origin
        xyz="0.36125 -1.0481E-07 0.0012658"
        rpy="0 0 0" />
      <mass
        value="5.0028" />
      <inertia
        ixx="0.0034222"
        ixy="-1.6329E-08"
        ixz="-0.0024305"
        iyy="0.24731"
        iyz="-8.1628E-09"
        izz="0.24587" />
    </inertial>
    <visual>
      <origin
        xyz="0 0 0"
        rpy="0 0 0" />
      <geometry>
        <mesh
          filename="package://RescueBot_Baugruppe.SLDASM/meshes/ellenbogen.STL" />
      </geometry>
      <material
        name="">
        <color
          rgba="1 1 1 1" />
      </material>
    </visual>
    <collision>
      <origin
        xyz="0 0 0"
        rpy="0 0 0" />
      <geometry>
        <mesh
          filename="package://RescueBot_Baugruppe.SLDASM/meshes/ellenbogen.STL" />
      </geometry>
    </collision>
  </link>
  <joint
    name="oberarm"
    type="continuous">
    <origin
      xyz="0 0.202999999999992 0.0249999999999935"
      rpy="-1.5707963267949 -0.740356965763116 1.5707963267949" />
    <parent
      link="schulterGelenk" />
    <child
      link="ellenbogen" />
    <axis
      xyz="0 0 1" />
  </joint>
  <link
    name="handgelenk">
    <inertial>
      <origin
        xyz="0.00329981903381138 3.03018172553848E-07 0.275415050864493"
        rpy="0 0 0" />
      <mass
        value="2.08500049128727" />
      <inertia
        ixx="0.0657758612518679"
        ixy="2.30546597680681E-08"
        ixz="-0.000811638992232931"
        iyy="0.0662386185749563"
        iyz="-1.19691438710517E-07"
        izz="0.000860169924723742" />
    </inertial>
    <visual>
      <origin
        xyz="0 0 0"
        rpy="0 0 0" />
      <geometry>
        <mesh
          filename="package://RescueBot_Baugruppe.SLDASM/meshes/handgelenk.STL" />
      </geometry>
      <material
        name="">
        <color
          rgba="1 1 1 1" />
      </material>
    </visual>
    <collision>
      <origin
        xyz="0 0 0"
        rpy="0 0 0" />
      <geometry>
        <mesh
          filename="package://RescueBot_Baugruppe.SLDASM/meshes/handgelenk.STL" />
      </geometry>
    </collision>
  </link>
  <joint
    name="unterarm"
    type="continuous">
    <origin
      xyz="0.74500000000001 0 0"
      rpy="2.65796523927005 1.5707963267949 0" />
    <parent
      link="ellenbogen" />
    <child
      link="handgelenk" />
    <axis
      xyz="1 0 0" />
  </joint>
  <link
    name="handgelenk2">
    <inertial>
      <origin
        xyz="0.0020001 -0.00021441 0.063182"
        rpy="0 0 0" />
      <mass
        value="0.20444" />
      <inertia
        ixx="0.00058668"
        ixy="4.7794E-10"
        ixz="-8.0139E-11"
        iyy="0.00059571"
        iyz="4.0845E-07"
        izz="2.5888E-05" />
    </inertial>
    <visual>
      <origin
        xyz="0 0 0"
        rpy="0 0 0" />
      <geometry>
        <mesh
          filename="package://RescueBot_Baugruppe.SLDASM/meshes/handgelenk2.STL" />
      </geometry>
      <material
        name="">
        <color
          rgba="1 1 1 1" />
      </material>
    </visual>
    <collision>
      <origin
        xyz="0 0 0"
        rpy="0 0 0" />
      <geometry>
        <mesh
          filename="package://RescueBot_Baugruppe.SLDASM/meshes/handgelenk2.STL" />
      </geometry>
    </collision>
  </link>
  <joint
    name="hand"
    type="continuous">
    <origin
      xyz="0 0 0.575"
      rpy="-1.96362785676128 0 0" />
    <parent
      link="handgelenk" />
    <child
      link="handgelenk2" />
    <axis
      xyz="1 0 0" />
  </joint>
  <link
    name="köchel">
    <inertial>
      <origin
        xyz="0.0014891 -1.1102E-16 -5.5511E-17"
        rpy="0 0 0" />
      <mass
        value="0.038419" />
      <inertia
        ixx="3.2401E-05"
        ixy="-5.5057E-21"
        ixz="3.9202E-20"
        iyy="2.5479E-05"
        iyz="-5.421E-20"
        izz="7.8708E-06" />
    </inertial>
    <visual>
      <origin
        xyz="0 0 0"
        rpy="0 0 0" />
      <geometry>
        <mesh
          filename="package://RescueBot_Baugruppe.SLDASM/meshes/köchel.STL" />
      </geometry>
      <material
        name="">
        <color
          rgba="0.86667 0.9098 1 1" />
      </material>
    </visual>
    <collision>
      <origin
        xyz="0 0 0"
        rpy="0 0 0" />
      <geometry>
        <mesh
          filename="package://RescueBot_Baugruppe.SLDASM/meshes/köchel.STL" />
      </geometry>
    </collision>
  </link>
  <joint
    name="hand2"
    type="continuous">
    <origin
      xyz="0.00200000000000047 0 0.168317889650684"
      rpy="2.20889980848183 -1.5707963267949 0" />
    <parent
      link="handgelenk2" />
    <child
      link="köchel" />
    <axis
      xyz="1 0 0" />
  </joint>
  <link
    name="fingergelenk">
    <inertial>
      <origin
        xyz="-0.040008 3.3307E-16 -0.04427"
        rpy="0 0 0" />
      <mass
        value="0.04986" />
      <inertia
        ixx="7.0635E-06"
        ixy="-2.3717E-20"
        ixz="-7.2289E-20"
        iyy="4.1966E-05"
        iyz="-1.117E-20"
        izz="4.8198E-05" />
    </inertial>
    <visual>
      <origin
        xyz="0 0 0"
        rpy="0 0 0" />
      <geometry>
        <mesh
          filename="package://RescueBot_Baugruppe.SLDASM/meshes/fingergelenk.STL" />
      </geometry>
      <material
        name="">
        <color
          rgba="0.75294 0 0 1" />
      </material>
    </visual>
    <collision>
      <origin
        xyz="0 0 0"
        rpy="0 0 0" />
      <geometry>
        <mesh
          filename="package://RescueBot_Baugruppe.SLDASM/meshes/fingergelenk.STL" />
      </geometry>
    </collision>
  </link>
  <joint
    name="finger"
    type="continuous">
    <origin
      xyz="0.124825859230761 0 0"
      rpy="-3.14159265358979 0 3.14159265358979" />
    <parent
      link="köchel" />
    <child
      link="fingergelenk" />
    <axis
      xyz="1 0 0" />
  </joint>
</robot>