<?xml version="1.0" encoding="utf-8"?>
<!-- This URDF was automatically created by SolidWorks to URDF Exporter! Originally created by Stephen Brawner (brawner@gmail.com) 
     Commit Version: 1.5.1-0-g916b5db  Build Version: 1.5.7152.31018
     For more information, please see http://wiki.ros.org/sw_urdf_exporter -->
<robot
  name="RescueBot_Baugruppe.SLDASM">
  <link
    name="base_link">
    <inertial>
      <origin
        xyz="7.2718E-07 -0.18 0.18323"
        rpy="0 0 0" />
      <mass
        value="325.51" />
      <inertia
        ixx="114.12"
        ixy="-0.0029457"
        ixz="-1.016E-05"
        iyy="44.651"
        iyz="11.453"
        izz="140.83" />
    </inertial>
    <visual>
      <origin
        xyz="0 0 0"
        rpy="0 0 0" />
      <geometry>
        <mesh
          filename="package://RescueBot_Baugruppe.SLDASM/meshes/base_link.STL" />
      </geometry>
      <material
        name="">
        <color
          rgba="0.79216 0.81961 0.93333 1" />
      </material>
    </visual>
    <collision>
      <origin
        xyz="0 0 0"
        rpy="0 0 0" />
      <geometry>
        <mesh
          filename="package://RescueBot_Baugruppe.SLDASM/meshes/base_link.STL" />
      </geometry>
    </collision>
  </link>
  <link
    name="drehplatte">
    <inertial>
      <origin
        xyz="-5.5511E-17 0.013893 0.00060356"
        rpy="0 0 0" />
      <mass
        value="0.42188" />
      <inertia
        ixx="0.0005517"
        ixy="1.3129E-20"
        ixz="1.3553E-19"
        iyy="0.0010552"
        iyz="-6.5402E-06"
        izz="0.00060462" />
    </inertial>
    <visual>
      <origin
        xyz="0 0 0"
        rpy="0 0 0" />
      <geometry>
        <mesh
          filename="package://RescueBot_Baugruppe.SLDASM/meshes/drehplatte.STL" />
      </geometry>
      <material
        name="myMat">
        <color
          rgba="261 2 2 1" />
      </material>
    </visual>
    <collision>
      <origin
        xyz="0 0 0"
        rpy="0 0 0" />
      <geometry>
        <mesh
          filename="package://RescueBot_Baugruppe.SLDASM/meshes/drehplatte.STL" />
      </geometry>
    </collision>
  </link>
  <joint
    name="Dreplatte"
    type="continuous">
    <origin
      xyz="0 -0.772382229042563 0.591167457544184"
      rpy="1.5707963267949 0 -0.563242507888074" />
    <parent
      link="base_link" />
    <child
      link="drehplatte" />
    <axis
      xyz="0 1 0" />
  </joint>
  <link
    name="oberarm">
    <inertial>
      <origin
        xyz="-1.1102E-16 0.013603 -0.1102"
        rpy="0 0 0" />
      <mass
        value="0.27688" />
      <inertia
        ixx="0.0028368"
        ixy="6.5052E-19"
        ixz="6.9457E-18"
        iyy="0.0029288"
        iyz="4.2998E-05"
        izz="0.00014291" />
    </inertial>
    <visual>
      <origin
        xyz="0 0 0"
        rpy="0 0 0" />
      <geometry>
        <mesh
          filename="package://RescueBot_Baugruppe.SLDASM/meshes/oberarm.STL" />
      </geometry>
      <material
        name="">
        <color
          rgba="0.79216 0.81961 0.93333 1" />
      </material>
    </visual>
    <collision>
      <origin
        xyz="0 0 0"
        rpy="0 0 0" />
      <geometry>
        <mesh
          filename="package://RescueBot_Baugruppe.SLDASM/meshes/oberarm.STL" />
      </geometry>
    </collision>
  </link>
  <joint
    name="Oberarm"
    type="continuous">
    <origin
      xyz="0 0.06 0.015"
      rpy="-2.4448 0 3.1416" />
    <parent
      link="drehplatte" />
    <child
      link="oberarm" />
    <axis
      xyz="1 0 0" />
  </joint>
  <link
    name="unterarm">
    <inertial>
      <origin
        xyz="1.99840144432528E-15 0 0.210348634659313"
        rpy="0 0 0" />
      <mass
        value="0.138646560275947" />
      <inertia
        ixx="0.00226186597161406"
        ixy="0"
        ixz="-8.382873320739E-18"
        iyy="0.00226195290728649"
        iyz="1.53101205216215E-18"
        izz="7.31445576653655E-06" />
    </inertial>
    <visual>
      <origin
        xyz="0 0 0"
        rpy="0 0 0" />
      <geometry>
        <mesh
          filename="package://RescueBot_Baugruppe.SLDASM/meshes/unterarm.STL" />
      </geometry>
      <material
        name="">
        <color
          rgba="0.792156862745098 0.819607843137255 0.933333333333333 1" />
      </material>
    </visual>
    <collision>
      <origin
        xyz="0 0 0"
        rpy="0 0 0" />
      <geometry>
        <mesh
          filename="package://RescueBot_Baugruppe.SLDASM/meshes/unterarm.STL" />
      </geometry>
    </collision>
  </link>
  <joint
    name="Unterarm"
    type="continuous">
    <origin
      xyz="0 0.0150000000000005 -0.270000000000002"
      rpy="-2.07124984213266 0 3.14159265358979" />
    <parent
      link="oberarm" />
    <child
      link="unterarm" />
    <axis
      xyz="1 0 0" />
  </joint>
  <link
    name="hand">
    <inertial>
      <origin
        xyz="3.88578058618805E-15 -2.22044604925031E-16 0.0323821054589315"
        rpy="0 0 0" />
      <mass
        value="0.00679092879672445" />
      <inertia
        ixx="3.69001755878313E-06"
        ixy="-1.52201232709757E-22"
        ixz="1.9078093647923E-20"
        iyy="3.68868810876696E-06"
        iyz="3.51274654829831E-20"
        izz="1.49575534008504E-07" />
    </inertial>
    <visual>
      <origin
        xyz="0 0 0"
        rpy="0 0 0" />
      <geometry>
        <mesh
          filename="package://RescueBot_Baugruppe.SLDASM/meshes/hand.STL" />
      </geometry>
      <material
        name="">
        <color
          rgba="0.792156862745098 0.819607843137255 0.933333333333333 1" />
      </material>
    </visual>
    <collision>
      <origin
        xyz="0 0 0"
        rpy="0 0 0" />
      <geometry>
        <mesh
          filename="package://RescueBot_Baugruppe.SLDASM/meshes/hand.STL" />
      </geometry>
    </collision>
  </link>
  <joint
    name="Hand"
    type="continuous">
    <origin
      xyz="0 0 0.430000000000003"
      rpy="-0.332130576060565 0 0" />
    <parent
      link="unterarm" />
    <child
      link="hand" />
    <axis
      xyz="1 0 0" />
  </joint>
</robot>