<?xml version="1.0" encoding="utf-8"?>
<!-- This URDF was automatically created by SolidWorks to URDF Exporter! Originally created by Stephen Brawner (brawner@gmail.com)
     Commit Version: 1.5.1-0-g916b5db  Build Version: 1.5.7152.31018
     For more information, please see http://wiki.ros.org/sw_urdf_exporter -->
<robot
  name="RescueBot_Baugruppe.SLDASM">
  <link
    name="base_link">
    <inertial>
      <origin
        xyz="-9.7259E-06 0.53594 0.7999"
        rpy="0 0 0" />
      <mass
        value="3.0727" />
      <inertia
        ixx="0.012272"
        ixy="2.9731E-06"
        ixz="2.5472E-05"
        iyy="0.0083734"
        iyz="2.9564E-05"
        izz="0.012523" />
    </inertial>
    <visual>
      <origin
        xyz="0 0 0"
        rpy="0 0 0" />
      <geometry>
        <mesh
          filename="package://RescueBot_Baugruppe.SLDASM/meshes/base_link.STL" />
      </geometry>
      <material
        name="">
        <color
          rgba="0.79216 0.81961 0.93333 1" />
      </material>
    </visual>
    <collision>
      <origin
        xyz="0 0 0"
        rpy="0 0 0" />
      <geometry>
        <mesh
          filename="package://RescueBot_Baugruppe.SLDASM/meshes/base_link.STL" />
      </geometry>
    </collision>
  </link>
  <link
    name="drehplatte">
    <inertial>
      <origin
        xyz="2.2676E-08 0.087777 -9.73E-05"
        rpy="0 0 0" />
      <mass
        value="3.0727" />
      <inertia
        ixx="0.012269"
        ixy="-3.7853E-09"
        ixz="-1.541E-08"
        iyy="0.0083734"
        iyz="2.9713E-05"
        izz="0.012525" />
    </inertial>
    <visual>
      <origin
        xyz="0 0 0"
        rpy="0 0 0" />
      <geometry>
        <mesh
          filename="package://RescueBot_Baugruppe.SLDASM/meshes/drehplatte.STL" />
      </geometry>
      <material
        name="">
        <color
          rgba="0.79216 0.81961 0.93333 1" />
      </material>
    </visual>
    <collision>
      <origin
        xyz="0 0 0"
        rpy="0 0 0" />
      <geometry>
        <mesh
          filename="package://RescueBot_Baugruppe.SLDASM/meshes/drehplatte.STL" />
      </geometry>
    </collision>
  </link>
  <joint
    name="Drehplatt"
    type="fixed">
    <origin
      xyz="0 -0.8 0.44817"
      rpy="1.5708 0 0.10036" />
    <parent
      link="base_link" />
    <child
      link="drehplatte" />
    <axis
      xyz="0 0 0" />
  </joint>
  <link
    name="oberarm">
    <inertial>
      <origin
        xyz="0.36125 -6.5238E-09 0.0012661"
        rpy="0 0 0" />
      <mass
        value="2.5014" />
      <inertia
        ixx="0.0017111"
        ixy="-3.7229E-09"
        ixz="-0.0012152"
        iyy="0.12365"
        iyz="-4.4685E-09"
        izz="0.12294" />
    </inertial>
    <visual>
      <origin
        xyz="0 0 0"
        rpy="0 0 0" />
      <geometry>
        <mesh
          filename="package://RescueBot_Baugruppe.SLDASM/meshes/oberarm.STL" />
      </geometry>
      <material
        name="">
        <color
          rgba="0.5 0.2 0.9 1" />
      </material>
    </visual>
    <collision>
      <origin
        xyz="0 0 0"
        rpy="0 0 0" />
      <geometry>
        <mesh
          filename="package://RescueBot_Baugruppe.SLDASM/meshes/oberarm.STL" />
      </geometry>
    </collision>
  </link>
  <joint
    name="Oberarm"
    type="continuous">
    <origin
      xyz="0 0.203 0.025"
      rpy="-1.5708 -1.2778 1.5708" />
    <parent
      link="drehplatte" />
    <child
      link="oberarm" />
    <axis
      xyz="0 0 1" />
  </joint>
  <link
    name="unterarm">
    <inertial>
      <origin
        xyz="0.0032998 -7.0657E-09 0.27542"
        rpy="0 0 0" />
      <mass
        value="1.0425" />
      <inertia
        ixx="0.032888"
        ixy="1.0183E-08"
        ixz="-0.00040582"
        iyy="0.033119"
        iyz="-6.0686E-08"
        izz="0.00043008" />
    </inertial>
    <visual>
      <origin
        xyz="0 0 0"
        rpy="0 0 0" />
      <geometry>
        <mesh
          filename="package://RescueBot_Baugruppe.SLDASM/meshes/unterarm.STL" />
      </geometry>
      <material
        name="">
        <color
          rgba="0.79216 0.81961 0.93333 1" />
      </material>
    </visual>
    <collision>
      <origin
        xyz="0 0 0"
        rpy="0 0 0" />
      <geometry>
        <mesh
          filename="package://RescueBot_Baugruppe.SLDASM/meshes/unterarm.STL" />
      </geometry>
    </collision>
  </link>
  <joint
    name="Unterarm"
    type="continuous">
    <origin
      xyz="0.745 0 0"
      rpy="1.8898 1.5708 0" />
    <parent
      link="oberarm" />
    <child
      link="unterarm" />
    <axis
      xyz="1 0 0" />
  </joint>
  <link
    name="hand">
    <inertial>
      <origin
        xyz="0.002 -0.00021454 0.063182"
        rpy="0 0 0" />
      <mass
        value="0.10222" />
      <inertia
        ixx="0.00029334"
        ixy="8.3887E-11"
        ixz="4.649E-11"
        iyy="0.00029786"
        iyz="2.0447E-07"
        izz="1.2944E-05" />
    </inertial>
    <visual>
      <origin
        xyz="0 0 0"
        rpy="0 0 0" />
      <geometry>
        <mesh
          filename="package://RescueBot_Baugruppe.SLDASM/meshes/hand.STL" />
      </geometry>
      <material
        name="">
        <color
          rgba="0.79216 0.81961 0.93333 1" />
      </material>
    </visual>
    <collision>
      <origin
        xyz="0 0 0"
        rpy="0 0 0" />
      <geometry>
        <mesh
          filename="package://RescueBot_Baugruppe.SLDASM/meshes/hand.STL" />
      </geometry>
    </collision>
  </link>
  <joint
    name="Hand"
    type="continuous">
    <origin
      xyz="0 0 0.575"
      rpy="-0.82998 0 0" />
    <parent
      link="unterarm" />
    <child
      link="hand" />
    <axis
      xyz="1 0 0" />
  </joint>
  <link
    name="finger">
    <inertial>
      <origin
        xyz="-0.0025449 2.7867E-13 0.056704"
        rpy="0 0 0" />
      <mass
        value="0.09972" />
      <inertia
        ixx="1.4127E-05"
        ixy="-3.4644E-19"
        ixz="-1.5724E-17"
        iyy="8.3931E-05"
        iyz="-2.2446E-20"
        izz="9.6396E-05" />
    </inertial>
    <visual>
      <origin
        xyz="0 0 0"
        rpy="0 0 0" />
      <geometry>
        <mesh
          filename="package://RescueBot_Baugruppe.SLDASM/meshes/finger.STL" />
      </geometry>
      <material
        name="">
        <color
          rgba="0.75294 0 0 1" />
      </material>
    </visual>
    <collision>
      <origin
        xyz="0 0 0"
        rpy="0 0 0" />
      <geometry>
        <mesh
          filename="package://RescueBot_Baugruppe.SLDASM/meshes/finger.STL" />
      </geometry>
    </collision>
  </link>
  <joint
    name="Finger"
    type="fixed">
    <origin
      xyz="0.066137 0 0.32806"
      rpy="3.1416 1.5708 0" />
    <parent
      link="hand" />
    <child
      link="finger" />
    <axis
      xyz="0 0 0" />
  </joint>
</robot>
